<?xml version="1.0" ?>
<!-- Generated using onshape-to-robot -->
<!-- Onshape https://cad.onshape.com/documents/430ff184cf3dd9557aaff2be/w/b018c00d2300dcc36080a900/e/a30f3af671aa926642803c67 -->
<mujoco model="onshape_to_robot_69e9f0da9e87b1.61053623">
  <compiler angle="radian" meshdir="assets" autolimits="true"/>
  <default>
    <default class="onshape_to_robot_69e9f0da9e87b1.61053623">
      <joint frictionloss="0.1" armature="0.005"/>
      <position kp="50" dampratio="1"/>
      <default class="visual">
        <geom type="mesh" contype="0" conaffinity="0" group="2"/>
      </default>
      <default class="collision">
        <geom group="3"/>
      </default>
    </default>
  </default>
  <!-- Additional joints_properties.xml -->
  <default>
    <default class="perfect_actuator">
      <geom contype="0" conaffinity="0"/>
      <joint damping="0.095" frictionloss="0.001" armature="0.001" range="-1.5707963267948966 1.5707963267948966"/>
      <position kp="10.0" kv="0.0" forcerange="-10.0 10.0"/>
      <default class="chosen_actuator"/>
    </default>
    <default class="xc330m288t">
      <!-- probably wrong, would need to re-identify -->
      <geom contype="0" conaffinity="0"/>
      <joint damping="0.095" frictionloss="0.058" armature="0.0018"/>
      <position kp="2.54" kv="0.0" forcerange="-0.8 0.8"/>
    </default>
    <default class="sts3215_345">
      <!-- Standard sts3215 with 1/345 gear ratio -->
      <!-- Confident that this is realistic (mini duck walks with these values) -->
      <geom contype="0" conaffinity="0"/>
      <joint damping="0.56" frictionloss="0.068" armature="0.027"/>
      <position kp="17.11" kv="0.0" forcerange="-3.23 3.23"/>
    </default>
    <default class="sts3215_147">
      <!-- sts3215 with 1/147 gear ratio -->
      <!-- (Estimation based on the gear ratio difference) -->
      <geom contype="0" conaffinity="0"/>
      <joint damping="0.1" frictionloss="0.028" armature="0.011"/>
      <position kp="17.11" kv="0.0" forcerange="-1.35 1.35"/>
    </default>
  </default>
  <!-- Additional additional.xml -->
  <contact>
    <!-- <exclude name="exclude0" body1="torso" body2="sts32155"/> -->
  </contact>
  <default>
    <equality solref="0.002 1" solimp="0.99 0.999 0.0005 0.5 2"/>
  </default>
  <worldbody>
    <!-- Link l_wrist_interface -->
    <body name="l_wrist_interface" pos="0 0 0" quat="1 0 0 0" childclass="onshape_to_robot_69e9f0da9e87b1.61053623">
      <inertial pos="-0.0129274 0.00108786 0.0569858" mass="0.160126" fullinertia="0.000178597 0.000104501 0.000126051 1.46589e-05 2.9722e-05 -9.40751e-06"/>
      <!-- Part sts3032 -->
      <geom type="mesh" class="visual" pos="-0.00800001 -0.01845 0.070198" quat="0.5 0.5 0.5 0.5" mesh="sts3032" material="sts3032_material"/>
      <!-- Part finger_frame -->
      <geom type="mesh" class="visual" pos="-0.0115 -0.0245 0.1022" quat="0.5 0.5 -0.5 -0.5" mesh="finger_frame" material="finger_frame_material"/>
      <!-- Part sts3032_2 -->
      <geom type="mesh" class="visual" pos="7.5027e-05 -0.00786953 0.0332" quat="0.573576 -0 -0 -0.819152" mesh="sts3032" material="sts3032_material"/>
      <!-- Part bushing_0608_04 -->
      <geom type="mesh" class="visual" pos="-0.015 0.0083 0.0961543" quat="0.48674 -0.512917 0.48674 -0.512917" mesh="bushing_0608_04" material="bushing_0608_04_material"/>
      <!-- Part bushing_0608_04_2 -->
      <geom type="mesh" class="visual" pos="-0.015 -0.0245 0.1022" quat="0.5 -0.5 0.5 -0.5" mesh="bushing_0608_04" material="bushing_0608_04_material"/>
      <!-- Part bushing_0608_04_3 -->
      <geom type="mesh" class="visual" pos="-0.015 0.0404332 0.0850969" quat="0.470849 -0.527542 0.470849 -0.527542" mesh="bushing_0608_04" material="bushing_0608_04_material"/>
      <!-- Part bushing_0608_04_4 -->
      <geom type="mesh" class="visual" pos="-0.025 0.0083 0.0961543" quat="0.512917 0.48674 -0.512917 -0.48674" mesh="bushing_0608_04" material="bushing_0608_04_material"/>
      <!-- Part sts3032_3 -->
      <geom type="mesh" class="visual" pos="-0.00800001 0.000583436 0.0645128" quat="0.512917 0.48674 0.512917 0.48674" mesh="sts3032" material="sts3032_material"/>
      <!-- Part sts3032_4 -->
      <geom type="mesh" class="visual" pos="-0.00800001 -0.03055 0.070198" quat="0.5 0.5 0.5 0.5" mesh="sts3032" material="sts3032_material"/>
      <!-- Part l_hand_plate -->
      <geom type="mesh" class="visual" pos="-0.0115 -0.1245 0.1022" quat="0.5 0.5 -0.5 -0.5" mesh="l_hand_plate" material="l_hand_plate_material"/>
      <!-- Part sts3032_5 -->
      <geom type="mesh" class="visual" pos="-0.00800001 0.0126669 0.0638795" quat="0.512917 0.48674 0.512917 0.48674" mesh="sts3032" material="sts3032_material"/>
      <!-- Part sts3032_6 -->
      <geom type="mesh" class="visual" pos="-0.00800001 0.0307993 0.0539855" quat="0.527542 0.470849 0.527542 0.470849" mesh="sts3032" material="sts3032_material"/>
      <!-- Part finger_frame_2 -->
      <geom type="mesh" class="visual" pos="-0.0115 0.0083 0.0961543" quat="0.512917 0.48674 -0.512917 -0.48674" mesh="finger_frame" material="finger_frame_material"/>
      <!-- Part bushing_0608_04_5 -->
      <geom type="mesh" class="visual" pos="0.0280778 -0.0245 0.0262" quat="0.819152 -0 0 0.573576" mesh="bushing_0608_04" material="bushing_0608_04_material"/>
      <!-- Part sts3032_7 -->
      <geom type="mesh" class="visual" pos="-0.00800001 0.0428216 0.0526158" quat="0.527542 0.470849 0.527542 0.470849" mesh="sts3032" material="sts3032_material"/>
      <!-- Part sts3032_8 -->
      <geom type="mesh" class="visual" pos="-0.00406342 -0.0192398 0.0332" quat="0.573576 -0 -0 -0.819152" mesh="sts3032" material="sts3032_material"/>
      <!-- Part bushing_0608_04_6 -->
      <geom type="mesh" class="visual" pos="-0.025 -0.0245 0.1022" quat="0.5 0.5 -0.5 -0.5" mesh="bushing_0608_04" material="bushing_0608_04_material"/>
      <!-- Part bushing_0608_04_7 -->
      <geom type="mesh" class="visual" pos="-0.025 0.0404332 0.0850969" quat="0.527542 0.470849 -0.527542 -0.470849" mesh="bushing_0608_04" material="bushing_0608_04_material"/>
      <!-- Part l_wrist_interface -->
      <geom type="mesh" class="visual" pos="-0.0115 -0.1245 0.1022" quat="0.5 0.5 -0.5 -0.5" mesh="l_wrist_interface" material="l_wrist_interface_material"/>
      <!-- Part bushing_0608_04_8 -->
      <geom type="mesh" class="visual" pos="0.0280778 -0.0245 0.0162" quat="0 0.819152 0.573576 -0" mesh="bushing_0608_04" material="bushing_0608_04_material"/>
      <!-- Part finger_frame_3 -->
      <geom type="mesh" class="visual" pos="-0.0115 0.0404332 0.0850969" quat="0.527542 0.470849 -0.527542 -0.470849" mesh="finger_frame" material="finger_frame_material"/>
      <!-- Part finger_frame_4 -->
      <geom type="mesh" class="visual" pos="0.0280778 -0.0245 0.0297" quat="0 0.819152 0.573576 -0" mesh="finger_frame" material="finger_frame_material"/>
      <!-- Frame closing_1 (1)_2 -->
      <site group="3" name="closing_1 (1)_2" pos="-0.015 -0.0245 0.1022" quat="0.5 0.5 -0.5 -0.5"/>
      <!-- Frame closing_1 (1)_2_z -->
      <site group="3" name="closing_1 (1)_2_z" pos="-0.115 -0.0245 0.1022" quat="0.5 0.5 -0.5 -0.5"/>
      <!-- Frame closing_1 (2)_2 -->
      <site group="3" name="closing_1 (2)_2" pos="-0.015 0.0083 0.0961543" quat="0.512917 0.48674 -0.512917 -0.48674"/>
      <!-- Frame closing_1 (2)_2_z -->
      <site group="3" name="closing_1 (2)_2_z" pos="-0.115 0.0083 0.0961543" quat="0.512917 0.48674 -0.512917 -0.48674"/>
      <!-- Frame closing_1 (3)_2 -->
      <site group="3" name="closing_1 (3)_2" pos="-0.015 0.0404332 0.0850969" quat="0.527542 0.470849 -0.527542 -0.470849"/>
      <!-- Frame closing_1 (3)_2_z -->
      <site group="3" name="closing_1 (3)_2_z" pos="-0.115 0.0404332 0.0850969" quat="0.527542 0.470849 -0.527542 -0.470849"/>
      <!-- Frame closing_1 (4)_2 -->
      <site group="3" name="closing_1 (4)_2" pos="0.0280778 -0.0245 0.0262" quat="0 0.819152 0.573576 -0"/>
      <!-- Frame closing_1 (4)_2_z -->
      <site group="3" name="closing_1 (4)_2_z" pos="0.0280778 -0.0245 -0.0738" quat="0 0.819152 0.573576 -0"/>
      <!-- Link custom_servo_horn -->
      <body name="custom_servo_horn" pos="-0.0046 -0.01845 0.070198" quat="0.5 -0.5 -0.5 0.5">
        <!-- Joint from l_wrist_interface to custom_servo_horn -->
        <joint axis="0 0 1" name="finger1_motor1" type="hinge" range="-1.3962634015954714 1.396263401595456"/>
        <inertial pos="0.006 0 -0.00345938" mass="0.000410988" fullinertia="4.636e-09 4.636e-09 1e-09 0 0 0"/>
        <!-- Part rotule_ball -->
        <geom type="mesh" class="visual" pos="0.006 0 -0.0038" quat="0 -0 0 1" mesh="rotule_ball" material="rotule_ball_material"/>
        <!-- Part ph_pan_head_screw_m2x0_40_x_10__2803432263e518bbd16bccbbef8784ed -->
        <geom type="mesh" class="visual" pos="0.006 0 -0.0083" quat="0 -0.707107 0.707107 0" mesh="ph_pan_head_screw_m2x0_40_x_10__2803432263e518bbd16bccbbef8784ed" material="ph_pan_head_screw_m2x0_40_x_10__2803432263e518bbd16bccbbef8784ed_material"/>
        <!-- Part custom_servo_horn -->
        <geom type="mesh" class="visual" pos="0 0 0.00340001" quat="0 1 0 0" mesh="custom_servo_horn" material="custom_servo_horn_material"/>
        <!-- Link ball_link -->
        <body name="ball_link" pos="0.006 0 -0.0038" quat="0.454049 0.0688602 0.888252 -0.0103254">
          <!-- Joint from custom_servo_horn to ball_link -->
          <joint axis="0 0 1" name="passive_ball1" type="ball"/>
          <inertial pos="-0 -0.0165 -0" mass="0.000463323" fullinertia="6.4012e-08 1.597e-09 6.4012e-08 0 -0 -0"/>
          <!-- Part rotule_lever -->
          <geom type="mesh" class="visual" pos="-0 -0.033 0" quat="0 0.707107 0 0.707107" mesh="rotule_lever" material="rotule_lever_material"/>
          <!-- Part rotule_lever_2 -->
          <geom type="mesh" class="visual" pos="0 0 -0" quat="1 -0 -0 -0" mesh="rotule_lever" material="rotule_lever_material"/>
          <!-- Part m2_rod_l18 -->
          <geom type="mesh" class="visual" pos="-0 -0.0335 0" quat="0 -0 0 1" mesh="m2_rod_l18" material="m2_rod_l18_material"/>
          <!-- Part spacer -->
          <geom type="mesh" class="visual" pos="-0 -0.033 0" quat="0 -0 0 1" mesh="spacer" material="spacer_material"/>
          <!-- Link rotule_ball -->
          <body name="rotule_ball" pos="-0 -0.033 0" quat="0.707107 -0 -0.707107 -0">
            <!-- Joint from ball_link to rotule_ball -->
            <joint axis="0 0 1" name="passive_ball2" type="ball"/>
            <inertial pos="-0.00548633 -0.014351 -0.00289129" mass="0.00277119" fullinertia="7.67403e-07 1.02879e-07 7.98661e-07 1.11073e-07 -1.9663e-08 3.893e-09"/>
            <!-- Part link -->
            <geom type="mesh" class="visual" pos="-0.0130003 -0.00274643 0.00482718" quat="0.13296 0.282739 0.195077 -0.929691" mesh="link" material="link_material"/>
            <!-- Part ph_pan_head_screw_m2x0_40_x_10__2803432263e518bbd16bccbbef8784ed_2 -->
            <geom type="mesh" class="visual" pos="0.00362143 0.000616102 0.00259917" quat="0.770233 -0.292418 0.354535 -0.442197" mesh="ph_pan_head_screw_m2x0_40_x_10__2803432263e518bbd16bccbbef8784ed" material="ph_pan_head_screw_m2x0_40_x_10__2803432263e518bbd16bccbbef8784ed_material"/>
            <!-- Part rotule_ball_2 -->
            <geom type="mesh" class="visual" pos="-0 0 -0" quat="0.0439232 -0.857317 -0.231957 0.457465" mesh="rotule_ball" material="rotule_ball_material"/>
            <!-- Part ph_pan_head_screw_m2x0_40_x_10__2803432263e518bbd16bccbbef8784ed_3 -->
            <geom type="mesh" class="visual" pos="-0.0165781 -0.00282038 -0.0118984" quat="0.292418 0.770233 -0.442197 -0.354535" mesh="ph_pan_head_screw_m2x0_40_x_10__2803432263e518bbd16bccbbef8784ed" material="ph_pan_head_screw_m2x0_40_x_10__2803432263e518bbd16bccbbef8784ed_material"/>
            <!-- Part rotule_ball_3 -->
            <geom type="mesh" class="visual" pos="-0.0129567 -0.00220428 -0.00929926" quat="0.857317 0.0439232 0.457465 0.231957" mesh="rotule_ball" material="rotule_ball_material"/>
            <!-- Frame closing_ball1_2 -->
            <site group="3" name="closing_ball1_2" pos="-0.0129567 -0.00220428 -0.00929926" quat="0.770233 -0.292418 0.354535 -0.442197"/>
            <!-- Link std00333_plast_tcb_torx_2_5x8__configuration_copy_of_default -->
            <body name="std00333_plast_tcb_torx_2_5x8__configuration_copy_of_default" pos="-0.0116863 -0.000379119 -0.000854295" quat="0.770233 -0.292418 0.354535 -0.442197">
              <!-- Joint from rotule_ball to std00333_plast_tcb_torx_2_5x8__configuration_copy_of_default -->
              <joint axis="0 0 1" name="passive2 (1)" type="hinge"/>
              <inertial pos="-0.0049016 -0.00891862 0.00225" mass="0.00201325" fullinertia="9.7548e-08 4.2802e-08 1.16807e-07 -4.3109e-08 -0 -0"/>
              <!-- Part std00333_plast_tcb_torx_2_5x8__configuration_copy_of_default -->
              <geom type="mesh" class="visual" pos="-0.0104517 -0.0190172 0.00225" quat="0.608614 -0.359985 0.608614 0.359985" mesh="std00333_plast_tcb_torx_2_5x8__configuration_copy_of_default" material="std00333_plast_tcb_torx_2_5x8__configuration_copy_of_default_material"/>
              <!-- Part gimbal -->
              <geom type="mesh" class="visual" pos="-0.00288986 -0.0052582 0.00225" quat="0.359985 0.608614 0.359985 -0.608614" mesh="gimbal" material="gimbal_material"/>
              <!-- Part plain_washer_large_grade_a_m2_5__9a369f0dc77bf9c598cdf3fb468977e5 -->
              <geom type="mesh" class="visual" pos="-0.00953654 -0.0173521 0.00225" quat="0.359985 0.608614 0.359985 -0.608614" mesh="plain_washer_large_grade_a_m2_5__9a369f0dc77bf9c598cdf3fb468977e5" material="plain_washer_large_grade_a_m2_5__9a369f0dc77bf9c598cdf3fb468977e5_material"/>
              <!-- Part parallel_pin_2_x_10__fee063fca0c8b40e46bbc4ffff61d999 -->
              <geom type="mesh" class="visual" pos="0 0 0.00225" quat="0.86071 0 -0 0.509095" mesh="parallel_pin_2_x_10__fee063fca0c8b40e46bbc4ffff61d999" material="parallel_pin_2_x_10__fee063fca0c8b40e46bbc4ffff61d999_material"/>
              <!-- Frame closing_1 (1)_1 -->
              <site group="3" name="closing_1 (1)_1" pos="-0.00457561 -0.00832549 0.00225" quat="0.359985 0.608614 0.359985 -0.608614"/>
              <!-- Frame closing_1 (1)_1_z -->
              <site group="3" name="closing_1 (1)_1_z" pos="-0.05274 -0.0959622 0.00225" quat="0.359985 0.608614 0.359985 -0.608614"/>
              <!-- Frame closing_3 (1)_2 -->
              <site group="3" name="closing_3 (1)_2" pos="-0.00288986 -0.0052582 -0.00275" quat="0.968599 -0 0 -0.248629"/>
              <!-- Frame closing_3 (1)_2_z -->
              <site group="3" name="closing_3 (1)_2_z" pos="-0.00288986 -0.0052582 0.09725" quat="0.968599 -0 0 -0.248629"/>
            </body>
            <!-- Link parallel_pin_2_x_10__fee063fca0c8b40e46bbc4ffff61d999 -->
            <body name="parallel_pin_2_x_10__fee063fca0c8b40e46bbc4ffff61d999" pos="0.00360668 -0.0485439 -0.00416606" quat="0.292418 0.770233 -0.442197 -0.354535">
              <!-- Joint from rotule_ball to parallel_pin_2_x_10__fee063fca0c8b40e46bbc4ffff61d999 -->
              <joint axis="0 0 1" name="passive4 (1)" type="hinge"/>
              <inertial pos="0.0150962 -0.0127974 0.00225" mass="0.00540375" fullinertia="3.33567e-07 5.77676e-07 7.69492e-07 3.27688e-07 -0 -0"/>
              <!-- Part std00447_thermoplastique_m2_5x6__configuration_default -->
              <geom type="mesh" class="visual" pos="0.0201331 -0.0157613 -0.00735" quat="0.860105 0 0 0.510117" mesh="std00447_thermoplastique_m2_5x6__configuration_default" material="std00447_thermoplastique_m2_5x6__configuration_default_material"/>
              <!-- Part std00447_thermoplastique_m2_5x6__configuration_default_2 -->
              <geom type="mesh" class="visual" pos="0.0201331 -0.0157613 0.01185" quat="0 -0.860105 -0.510117 0" mesh="std00447_thermoplastique_m2_5x6__configuration_default" material="std00447_thermoplastique_m2_5x6__configuration_default_material"/>
              <!-- Part distal -->
              <geom type="mesh" class="visual" pos="-0.0457364 0.0189381 0.00225" quat="0.360707 -0.608186 -0.360707 -0.608186" mesh="distal" material="distal_material"/>
              <!-- Part distal_shell -->
              <geom type="mesh" class="visual" pos="-0.0457364 0.0189381 0.00225" quat="0.360707 -0.608186 -0.360707 -0.608186" mesh="distal_shell" material="distal_shell_material"/>
              <!-- Part parallel_pin_2_x_10__fee063fca0c8b40e46bbc4ffff61d999_2 -->
              <geom type="mesh" class="visual" pos="0 0 0.00225" quat="0 0.510117 -0.860105 0" mesh="parallel_pin_2_x_10__fee063fca0c8b40e46bbc4ffff61d999" material="parallel_pin_2_x_10__fee063fca0c8b40e46bbc4ffff61d999_material"/>
              <!-- Frame tip1 -->
              <site group="3" name="tip1" pos="0.0283456 -0.0266027 0.00225" quat="0.348133 -0.348133 0.61547 -0.61547"/>
              <!-- Link parallel_pin_2_x_16__da4b7ddbe9d803fe3fbc70f2e822b99b -->
              <body name="parallel_pin_2_x_16__da4b7ddbe9d803fe3fbc70f2e822b99b" pos="-0.000105947 -0.00599906 0.00655" quat="0 -1 -0.000555496 -0">
                <!-- Joint from parallel_pin_2_x_10__fee063fca0c8b40e46bbc4ffff61d999 to parallel_pin_2_x_16__da4b7ddbe9d803fe3fbc70f2e822b99b -->
                <joint axis="0 0 1" name="passive_5 (1)" type="hinge"/>
                <inertial pos="-0.0249171 -0.00392936 0.0052354" mass="0.0101851" fullinertia="4.96149e-07 2.52849e-06 2.3577e-06 2.4514e-08 1.19e-10 3.04e-10"/>
                <!-- Part std00447_thermoplastique_m2_5x6__configuration_default_3 -->
                <geom type="mesh" class="visual" pos="-0.022 -0.004 -0.00655" quat="0.707107 0 -0 -0.707107" mesh="std00447_thermoplastique_m2_5x6__configuration_default" material="std00447_thermoplastique_m2_5x6__configuration_default_material"/>
                <!-- Part std00447_thermoplastique_m2_5x6__configuration_default_4 -->
                <geom type="mesh" class="visual" pos="-0.022 -0.004 0.01685" quat="0 -0.707107 0.707107 -0" mesh="std00447_thermoplastique_m2_5x6__configuration_default" material="std00447_thermoplastique_m2_5x6__configuration_default_material"/>
                <!-- Part parallel_pin_2_x_16__da4b7ddbe9d803fe3fbc70f2e822b99b -->
                <geom type="mesh" class="visual" pos="-0.052 0 0.00515" quat="0.707107 -0 0 -0.707107" mesh="parallel_pin_2_x_16__da4b7ddbe9d803fe3fbc70f2e822b99b" material="parallel_pin_2_x_16__da4b7ddbe9d803fe3fbc70f2e822b99b_material"/>
                <!-- Part parallel_pin_2_x_16__da4b7ddbe9d803fe3fbc70f2e822b99b_2 -->
                <geom type="mesh" class="visual" pos="0 0 0.00515" quat="0.707107 -0 0 -0.707107" mesh="parallel_pin_2_x_16__da4b7ddbe9d803fe3fbc70f2e822b99b" material="parallel_pin_2_x_16__da4b7ddbe9d803fe3fbc70f2e822b99b_material"/>
                <!-- Part proximal_shell -->
                <geom type="mesh" class="visual" pos="-0.052 0 0.00515" quat="0.5 0.5 0.5 -0.5" mesh="proximal_shell" material="proximal_shell_material"/>
                <!-- Part proximal -->
                <geom type="mesh" class="visual" pos="-0.052 0 0.00525" quat="0.5 0.5 0.5 -0.5" mesh="proximal" material="proximal_material"/>
                <!-- Frame closing_3 (1)_1 -->
                <site group="3" name="closing_3 (1)_1" pos="-0.052 0 0" quat="1 0 0 -0"/>
                <!-- Frame closing_3 (1)_1_z -->
                <site group="3" name="closing_3 (1)_1_z" pos="-0.052 0 0.1" quat="1 0 0 -0"/>
              </body>
            </body>
          </body>
        </body>
      </body>
      <!-- Link rotule_ball_2 -->
      <body name="rotule_ball_2" pos="-0.0046 -0.03055 0.070198" quat="0.5 0.5 -0.5 -0.5">
        <!-- Joint from l_wrist_interface to rotule_ball_2 -->
        <joint axis="0 0 1" name="finger1_motor2" type="hinge" range="-1.39626340159546 1.3962634015954671"/>
        <inertial pos="0.006 0 -0.00345938" mass="0.000410988" fullinertia="4.636e-09 4.636e-09 1e-09 -0 0 0"/>
        <!-- Part custom_servo_horn_2 -->
        <geom type="mesh" class="visual" pos="0 0 0.00340001" quat="0 1 0 0" mesh="custom_servo_horn" material="custom_servo_horn_material"/>
        <!-- Part rotule_ball_4 -->
        <geom type="mesh" class="visual" pos="0.006 0 -0.0038" quat="0 0 -0 -1" mesh="rotule_ball" material="rotule_ball_material"/>
        <!-- Part ph_pan_head_screw_m2x0_40_x_10__2803432263e518bbd16bccbbef8784ed_4 -->
        <geom type="mesh" class="visual" pos="0.006 0 -0.0083" quat="0 -0.707107 0.707107 -0" mesh="ph_pan_head_screw_m2x0_40_x_10__2803432263e518bbd16bccbbef8784ed" material="ph_pan_head_screw_m2x0_40_x_10__2803432263e518bbd16bccbbef8784ed_material"/>
        <!-- Link m2_rod_l18 -->
        <body name="m2_rod_l18" pos="0.006 0 -0.0038" quat="0.0431156 0.908584 0.0413143 -0.413411">
          <!-- Joint from rotule_ball_2 to m2_rod_l18 -->
          <joint axis="0 0 1" name="passive_ball3" type="ball"/>
          <inertial pos="-0 -0.0165 -0" mass="0.000463323" fullinertia="6.4012e-08 1.597e-09 6.4012e-08 0 -0 -0"/>
          <!-- Part rotule_lever_3 -->
          <geom type="mesh" class="visual" pos="0 0 0" quat="1 -0 0 -0" mesh="rotule_lever" material="rotule_lever_material"/>
          <!-- Part spacer_2 -->
          <geom type="mesh" class="visual" pos="0 0 -0" quat="0.707107 -0 0.707107 0" mesh="spacer" material="spacer_material"/>
          <!-- Part m2_rod_l18_2 -->
          <geom type="mesh" class="visual" pos="0 0.0005 -0" quat="0.707107 -0 0.707107 0" mesh="m2_rod_l18" material="m2_rod_l18_material"/>
          <!-- Part rotule_lever_4 -->
          <geom type="mesh" class="visual" pos="0 -0.033 -0" quat="0 -0.707107 -0 -0.707107" mesh="rotule_lever" material="rotule_lever_material"/>
          <!-- Frame closing_ball1_1 -->
          <site group="3" name="closing_ball1_1" pos="0 -0.033 -0" quat="0 -0.707107 -0 -0.707107"/>
        </body>
      </body>
      <!-- Link custom_servo_horn_2 -->
      <body name="custom_servo_horn_2" pos="-0.0046 0.0126669 0.0638795" quat="0.48674 -0.512917 -0.48674 0.512917">
        <!-- Joint from l_wrist_interface to custom_servo_horn_2 -->
        <joint axis="0 0 1" name="finger2_motor1" type="hinge" range="-1.396263401595466 1.3962634015954614"/>
        <inertial pos="0.006 -0 -0.00345938" mass="0.000410988" fullinertia="4.636e-09 4.636e-09 1e-09 -0 0 -0"/>
        <!-- Part rotule_ball_5 -->
        <geom type="mesh" class="visual" pos="0.006 -0 -0.0038" quat="0.707107 -0 0 0.707107" mesh="rotule_ball" material="rotule_ball_material"/>
        <!-- Part ph_pan_head_screw_m2x0_40_x_10__2803432263e518bbd16bccbbef8784ed_5 -->
        <geom type="mesh" class="visual" pos="0.006 -0 -0.0083" quat="0 -0 -1 0" mesh="ph_pan_head_screw_m2x0_40_x_10__2803432263e518bbd16bccbbef8784ed" material="ph_pan_head_screw_m2x0_40_x_10__2803432263e518bbd16bccbbef8784ed_material"/>
        <!-- Part custom_servo_horn_3 -->
        <geom type="mesh" class="visual" pos="0 0 0.00340001" quat="0 1 0 0" mesh="custom_servo_horn" material="custom_servo_horn_material"/>
        <!-- Link ball_link_2 -->
        <body name="ball_link_2" pos="0.006 -0 -0.0038" quat="0.997565 0.0218794 -0.00405708 -0.0661032">
          <!-- Joint from custom_servo_horn_2 to ball_link_2 -->
          <joint axis="0 0 1" name="passive_ball4" type="ball"/>
          <inertial pos="-0 -0.0165 -0" mass="0.000463323" fullinertia="6.4012e-08 1.597e-09 6.4012e-08 0 -0 -0"/>
          <!-- Part rotule_lever_5 -->
          <geom type="mesh" class="visual" pos="0 0 -0" quat="1 -0 -0 0" mesh="rotule_lever" material="rotule_lever_material"/>
          <!-- Part rotule_lever_6 -->
          <geom type="mesh" class="visual" pos="0 -0.033 0" quat="0 -0.707107 -0 -0.707107" mesh="rotule_lever" material="rotule_lever_material"/>
          <!-- Part m2_rod_l18_3 -->
          <geom type="mesh" class="visual" pos="-0 0.0005 0" quat="0.707107 0 0.707107 0" mesh="m2_rod_l18" material="m2_rod_l18_material"/>
          <!-- Part spacer_3 -->
          <geom type="mesh" class="visual" pos="-0 0 -0" quat="0.707107 0 0.707107 -0" mesh="spacer" material="spacer_material"/>
          <!-- Link rotule_ball_3 -->
          <body name="rotule_ball_3" pos="0 -0.033 0" quat="0.707107 0 -0.707107 0">
            <!-- Joint from ball_link_2 to rotule_ball_3 -->
            <joint axis="0 0 1" name="passive_ball5" type="ball"/>
            <inertial pos="0.000919559 -0.014351 0.00613301" mass="0.00277119" fullinertia="8.06464e-07 1.02879e-07 7.596e-07 -6.2645e-08 -9.047e-09 -9.1804e-08"/>
            <!-- Part rotule_ball_6 -->
            <geom type="mesh" class="visual" pos="0.000180538 -0.00220428 0.0159474" quat="0.0210725 -0.226798 -0.971505 -0.0655443" mesh="rotule_ball" material="rotule_ball_material"/>
            <!-- Part ph_pan_head_screw_m2x0_40_x_10__2803432263e518bbd16bccbbef8784ed_6 -->
            <geom type="mesh" class="visual" pos="-5.04609e-05 0.000616102 -0.00445734" quat="0.0314463 -0.526588 0.847328 0.0612473" mesh="ph_pan_head_screw_m2x0_40_x_10__2803432263e518bbd16bccbbef8784ed" material="ph_pan_head_screw_m2x0_40_x_10__2803432263e518bbd16bccbbef8784ed_material"/>
            <!-- Part link_2 -->
            <geom type="mesh" class="visual" pos="0.0115889 -0.00274643 0.00761623" quat="0.114023 0.701859 -0.206717 0.672058" mesh="link" material="link_material"/>
            <!-- Part ph_pan_head_screw_m2x0_40_x_10__2803432263e518bbd16bccbbef8784ed_7 -->
            <geom type="mesh" class="visual" pos="0.000230999 -0.00282038 0.0204047" quat="0.526588 0.0314463 0.0612473 -0.847328" mesh="ph_pan_head_screw_m2x0_40_x_10__2803432263e518bbd16bccbbef8784ed" material="ph_pan_head_screw_m2x0_40_x_10__2803432263e518bbd16bccbbef8784ed_material"/>
            <!-- Part rotule_ball_7 -->
            <geom type="mesh" class="visual" pos="0 -0 0" quat="0.226798 0.0210725 -0.0655443 0.971505" mesh="rotule_ball" material="rotule_ball_material"/>
            <!-- Frame closing_ball2_2 -->
            <site group="3" name="closing_ball2_2" pos="0.000180538 -0.00220428 0.0159474" quat="0.0655443 -0.971505 0.226798 0.0210725"/>
            <!-- Link std00333_plast_tcb_torx_2_5x8__configuration_copy_of_default_2 -->
            <body name="std00333_plast_tcb_torx_2_5x8__configuration_copy_of_default_2" pos="0.00623277 -0.000379119 0.00992227" quat="0.0314463 -0.526588 0.847328 0.0612473">
              <!-- Joint from rotule_ball_3 to std00333_plast_tcb_torx_2_5x8__configuration_copy_of_default_2 -->
              <joint axis="0 0 1" name="passive2 (2)" type="hinge"/>
              <inertial pos="-0.0049016 -0.00891862 0.00225" mass="0.00201325" fullinertia="9.7548e-08 4.2802e-08 1.16807e-07 -4.3109e-08 0 0"/>
              <!-- Part parallel_pin_2_x_10__fee063fca0c8b40e46bbc4ffff61d999_3 -->
              <geom type="mesh" class="visual" pos="0 -0 0.00225" quat="0.86071 0 0 0.509095" mesh="parallel_pin_2_x_10__fee063fca0c8b40e46bbc4ffff61d999" material="parallel_pin_2_x_10__fee063fca0c8b40e46bbc4ffff61d999_material"/>
              <!-- Part std00333_plast_tcb_torx_2_5x8__configuration_copy_of_default_2 -->
              <geom type="mesh" class="visual" pos="-0.0104517 -0.0190172 0.00225" quat="0.608614 -0.359985 0.608614 0.359985" mesh="std00333_plast_tcb_torx_2_5x8__configuration_copy_of_default" material="std00333_plast_tcb_torx_2_5x8__configuration_copy_of_default_material"/>
              <!-- Part plain_washer_large_grade_a_m2_5__9a369f0dc77bf9c598cdf3fb468977e5_2 -->
              <geom type="mesh" class="visual" pos="-0.00953654 -0.0173521 0.00225" quat="0.359985 0.608614 0.359985 -0.608614" mesh="plain_washer_large_grade_a_m2_5__9a369f0dc77bf9c598cdf3fb468977e5" material="plain_washer_large_grade_a_m2_5__9a369f0dc77bf9c598cdf3fb468977e5_material"/>
              <!-- Part gimbal_2 -->
              <geom type="mesh" class="visual" pos="-0.00288986 -0.0052582 0.00225" quat="0.359985 0.608614 0.359985 -0.608614" mesh="gimbal" material="gimbal_material"/>
              <!-- Frame closing_1 (2)_1 -->
              <site group="3" name="closing_1 (2)_1" pos="-0.00457561 -0.00832549 0.00225" quat="0.359985 0.608614 0.359985 -0.608614"/>
              <!-- Frame closing_1 (2)_1_z -->
              <site group="3" name="closing_1 (2)_1_z" pos="-0.05274 -0.0959622 0.00225" quat="0.359985 0.608614 0.359985 -0.608614"/>
              <!-- Frame closing_3 (2)_2 -->
              <site group="3" name="closing_3 (2)_2" pos="-0.00288986 -0.0052582 -0.00275" quat="0.968599 -0 0 -0.248629"/>
              <!-- Frame closing_3 (2)_2_z -->
              <site group="3" name="closing_3 (2)_2_z" pos="-0.00288986 -0.0052582 0.09725" quat="0.968599 -0 0 -0.248629"/>
            </body>
            <!-- Link parallel_pin_2_x_10__fee063fca0c8b40e46bbc4ffff61d999_2 -->
            <body name="parallel_pin_2_x_10__fee063fca0c8b40e46bbc4ffff61d999_2" pos="-0.00549287 -0.0485439 -0.000438794" quat="0.526588 0.0314463 0.0612473 -0.847328">
              <!-- Joint from rotule_ball_3 to parallel_pin_2_x_10__fee063fca0c8b40e46bbc4ffff61d999_2 -->
              <joint axis="0 0 1" name="passive4 (2)" type="hinge"/>
              <inertial pos="0.0150962 -0.0127974 0.00225" mass="0.00540375" fullinertia="3.33567e-07 5.77676e-07 7.69492e-07 3.27688e-07 -0 -0"/>
              <!-- Part distal_2 -->
              <geom type="mesh" class="visual" pos="-0.0457364 0.0189381 0.00225" quat="0.360707 -0.608186 -0.360707 -0.608186" mesh="distal" material="distal_material"/>
              <!-- Part std00447_thermoplastique_m2_5x6__configuration_default_5 -->
              <geom type="mesh" class="visual" pos="0.0201331 -0.0157613 0.01185" quat="0 -0.860105 -0.510117 0" mesh="std00447_thermoplastique_m2_5x6__configuration_default" material="std00447_thermoplastique_m2_5x6__configuration_default_material"/>
              <!-- Part distal_shell_2 -->
              <geom type="mesh" class="visual" pos="-0.0457364 0.0189381 0.00225" quat="0.360707 -0.608186 -0.360707 -0.608186" mesh="distal_shell" material="distal_shell_material"/>
              <!-- Part std00447_thermoplastique_m2_5x6__configuration_default_6 -->
              <geom type="mesh" class="visual" pos="0.0201331 -0.0157613 -0.00735" quat="0.860105 -0 0 0.510117" mesh="std00447_thermoplastique_m2_5x6__configuration_default" material="std00447_thermoplastique_m2_5x6__configuration_default_material"/>
              <!-- Part parallel_pin_2_x_10__fee063fca0c8b40e46bbc4ffff61d999_4 -->
              <geom type="mesh" class="visual" pos="0 0 0.00225" quat="0 0.510117 -0.860105 0" mesh="parallel_pin_2_x_10__fee063fca0c8b40e46bbc4ffff61d999" material="parallel_pin_2_x_10__fee063fca0c8b40e46bbc4ffff61d999_material"/>
              <!-- Frame tip2 -->
              <site group="3" name="tip2" pos="0.0283456 -0.0266027 0.00225" quat="0.348133 -0.348133 0.61547 -0.61547"/>
              <!-- Link parallel_pin_2_x_16__da4b7ddbe9d803fe3fbc70f2e822b99b_2 -->
              <body name="parallel_pin_2_x_16__da4b7ddbe9d803fe3fbc70f2e822b99b_2" pos="-0.000105947 -0.00599906 0.00655" quat="0 1 0.000555496 -0">
                <!-- Joint from parallel_pin_2_x_10__fee063fca0c8b40e46bbc4ffff61d999_2 to parallel_pin_2_x_16__da4b7ddbe9d803fe3fbc70f2e822b99b_2 -->
                <joint axis="0 0 1" name="passive_5 (2)" type="hinge"/>
                <inertial pos="-0.0249171 -0.00392936 0.0052354" mass="0.0101851" fullinertia="4.96149e-07 2.52849e-06 2.3577e-06 2.4514e-08 1.19e-10 3.04e-10"/>
                <!-- Part parallel_pin_2_x_16__da4b7ddbe9d803fe3fbc70f2e822b99b_3 -->
                <geom type="mesh" class="visual" pos="0 -0 0.00515" quat="0.707107 -0 0 -0.707107" mesh="parallel_pin_2_x_16__da4b7ddbe9d803fe3fbc70f2e822b99b" material="parallel_pin_2_x_16__da4b7ddbe9d803fe3fbc70f2e822b99b_material"/>
                <!-- Part std00447_thermoplastique_m2_5x6__configuration_default_7 -->
                <geom type="mesh" class="visual" pos="-0.022 -0.004 0.01685" quat="0 0.707107 -0.707107 -0" mesh="std00447_thermoplastique_m2_5x6__configuration_default" material="std00447_thermoplastique_m2_5x6__configuration_default_material"/>
                <!-- Part std00447_thermoplastique_m2_5x6__configuration_default_8 -->
                <geom type="mesh" class="visual" pos="-0.022 -0.004 -0.00655" quat="0.707107 -0 0 -0.707107" mesh="std00447_thermoplastique_m2_5x6__configuration_default" material="std00447_thermoplastique_m2_5x6__configuration_default_material"/>
                <!-- Part proximal_2 -->
                <geom type="mesh" class="visual" pos="-0.052 0 0.00525" quat="0.5 0.5 0.5 -0.5" mesh="proximal" material="proximal_material"/>
                <!-- Part proximal_shell_2 -->
                <geom type="mesh" class="visual" pos="-0.052 0 0.00515" quat="0.5 0.5 0.5 -0.5" mesh="proximal_shell" material="proximal_shell_material"/>
                <!-- Part parallel_pin_2_x_16__da4b7ddbe9d803fe3fbc70f2e822b99b_4 -->
                <geom type="mesh" class="visual" pos="-0.052 0 0.00515" quat="0.707107 0 -0 -0.707107" mesh="parallel_pin_2_x_16__da4b7ddbe9d803fe3fbc70f2e822b99b" material="parallel_pin_2_x_16__da4b7ddbe9d803fe3fbc70f2e822b99b_material"/>
                <!-- Frame closing_3 (2)_1 -->
                <site group="3" name="closing_3 (2)_1" pos="-0.052 0 0" quat="1 -0 0 -0"/>
                <!-- Frame closing_3 (2)_1_z -->
                <site group="3" name="closing_3 (2)_1_z" pos="-0.052 0 0.1" quat="1 -0 0 -0"/>
              </body>
            </body>
          </body>
        </body>
      </body>
      <!-- Link rotule_ball_4 -->
      <body name="rotule_ball_4" pos="-0.0046 0.000583436 0.0645128" quat="0.512917 0.48674 -0.512917 -0.48674">
        <!-- Joint from l_wrist_interface to rotule_ball_4 -->
        <joint axis="0 0 1" name="finger2_motor2" type="hinge" range="-1.3962634015954085 1.3962634015955186"/>
        <inertial pos="0.006 0 -0.00345938" mass="0.000410988" fullinertia="4.636e-09 4.636e-09 1e-09 -0 -0 0"/>
        <!-- Part ph_pan_head_screw_m2x0_40_x_10__2803432263e518bbd16bccbbef8784ed_8 -->
        <geom type="mesh" class="visual" pos="0.006 0 -0.0083" quat="0 -0.707107 0.707107 0" mesh="ph_pan_head_screw_m2x0_40_x_10__2803432263e518bbd16bccbbef8784ed" material="ph_pan_head_screw_m2x0_40_x_10__2803432263e518bbd16bccbbef8784ed_material"/>
        <!-- Part rotule_ball_8 -->
        <geom type="mesh" class="visual" pos="0.006 0 -0.0038" quat="0 0 0 -1" mesh="rotule_ball" material="rotule_ball_material"/>
        <!-- Part custom_servo_horn_4 -->
        <geom type="mesh" class="visual" pos="-0 0 0.00340001" quat="0 1 0 0" mesh="custom_servo_horn" material="custom_servo_horn_material"/>
        <!-- Link ball_link_3 -->
        <body name="ball_link_3" pos="0.006 -0 -0.0038" quat="0.0553952 -0.00295595 -0.022298 -0.998211">
          <!-- Joint from rotule_ball_4 to ball_link_3 -->
          <joint axis="0 0 1" name="passive_ball6" type="ball"/>
          <inertial pos="-0 -0.0165 -0" mass="0.000463323" fullinertia="6.4012e-08 1.597e-09 6.4012e-08 0 -0 -0"/>
          <!-- Part rotule_lever_7 -->
          <geom type="mesh" class="visual" pos="0 -0.033 0" quat="0 -0.707107 -0 -0.707107" mesh="rotule_lever" material="rotule_lever_material"/>
          <!-- Part rotule_lever_8 -->
          <geom type="mesh" class="visual" pos="0 0 0" quat="1 -0 -0 -0" mesh="rotule_lever" material="rotule_lever_material"/>
          <!-- Part m2_rod_l18_4 -->
          <geom type="mesh" class="visual" pos="0 -0.0335 0" quat="0 0 -0 -1" mesh="m2_rod_l18" material="m2_rod_l18_material"/>
          <!-- Part spacer_4 -->
          <geom type="mesh" class="visual" pos="0 -0.033 0" quat="0 0 0 -1" mesh="spacer" material="spacer_material"/>
          <!-- Frame closing_ball2_1 -->
          <site group="3" name="closing_ball2_1" pos="0 -0.033 0" quat="0 -0.707107 -0 -0.707107"/>
        </body>
      </body>
      <!-- Link custom_servo_horn_3 -->
      <body name="custom_servo_horn_3" pos="-0.0046 0.0428216 0.0526158" quat="0.470849 -0.527542 -0.470849 0.527542">
        <!-- Joint from l_wrist_interface to custom_servo_horn_3 -->
        <joint axis="0 0 1" name="finger3_motor1" type="hinge" range="-1.396263401595482 1.3962634015954454"/>
        <inertial pos="0.006 -0 -0.00345938" mass="0.000410988" fullinertia="4.636e-09 4.636e-09 1e-09 -0 0 -0"/>
        <!-- Part rotule_ball_9 -->
        <geom type="mesh" class="visual" pos="0.006 -0 -0.0038" quat="0.707107 -0 0 0.707107" mesh="rotule_ball" material="rotule_ball_material"/>
        <!-- Part custom_servo_horn_5 -->
        <geom type="mesh" class="visual" pos="0 0 0.00340001" quat="0 1 0 0" mesh="custom_servo_horn" material="custom_servo_horn_material"/>
        <!-- Part ph_pan_head_screw_m2x0_40_x_10__2803432263e518bbd16bccbbef8784ed_9 -->
        <geom type="mesh" class="visual" pos="0.006 -0 -0.0083" quat="0 0 1 -0" mesh="ph_pan_head_screw_m2x0_40_x_10__2803432263e518bbd16bccbbef8784ed" material="ph_pan_head_screw_m2x0_40_x_10__2803432263e518bbd16bccbbef8784ed_material"/>
        <!-- Link ball_link_4 -->
        <body name="ball_link_4" pos="0.006 -0 -0.0038" quat="0.305724 0.0696249 0.949571 0.000851314">
          <!-- Joint from custom_servo_horn_3 to ball_link_4 -->
          <joint axis="0 0 1" name="passive_ball7" type="ball"/>
          <inertial pos="-0 -0.0165 -0" mass="0.000463323" fullinertia="6.4012e-08 1.597e-09 6.4012e-08 0 -0 -0"/>
          <!-- Part rotule_lever_9 -->
          <geom type="mesh" class="visual" pos="0 0 0" quat="1 -0 0 0" mesh="rotule_lever" material="rotule_lever_material"/>
          <!-- Part rotule_lever_10 -->
          <geom type="mesh" class="visual" pos="0 -0.033 0" quat="0 -0.707107 0 -0.707107" mesh="rotule_lever" material="rotule_lever_material"/>
          <!-- Part m2_rod_l18_5 -->
          <geom type="mesh" class="visual" pos="0 0.0005 0" quat="0.707107 -0 0.707107 0" mesh="m2_rod_l18" material="m2_rod_l18_material"/>
          <!-- Part spacer_5 -->
          <geom type="mesh" class="visual" pos="0 0 0" quat="0.707107 -0 0.707107 0" mesh="spacer" material="spacer_material"/>
          <!-- Link rotule_ball_5 -->
          <body name="rotule_ball_5" pos="0 -0.033 0" quat="0.707107 0 -0.707107 0">
            <!-- Joint from ball_link_4 to rotule_ball_5 -->
            <joint axis="0 0 1" name="passive_ball8" type="ball"/>
            <inertial pos="-0.00428878 -0.014351 -0.00447948" mass="0.00277119" fullinertia="7.82346e-07 1.02879e-07 7.83718e-07 1.04127e-07 -2.5109e-08 3.8857e-08"/>
            <!-- Part rotule_ball_10 -->
            <geom type="mesh" class="visual" pos="-0.00934617 -0.00220428 -0.0129229" quat="0.919585 0.00615592 0.314056 0.235998" mesh="rotule_ball" material="rotule_ball_material"/>
            <!-- Part rotule_ball_11 -->
            <geom type="mesh" class="visual" pos="0 0 -0" quat="0.00615592 -0.919585 -0.235998 0.314056" mesh="rotule_ball" material="rotule_ball_material"/>
            <!-- Part ph_pan_head_screw_m2x0_40_x_10__2803432263e518bbd16bccbbef8784ed_10 -->
            <geom type="mesh" class="visual" pos="-0.0119585 -0.00282038 -0.0165348" quat="0.217718 0.817121 -0.483368 -0.226424" mesh="ph_pan_head_screw_m2x0_40_x_10__2803432263e518bbd16bccbbef8784ed" material="ph_pan_head_screw_m2x0_40_x_10__2803432263e518bbd16bccbbef8784ed_material"/>
            <!-- Part link_3 -->
            <geom type="mesh" class="visual" pos="-0.0138598 -0.00274643 0.000463149" quat="0.162523 0.428173 0.171229 -0.872316" mesh="link" material="link_material"/>
            <!-- Part ph_pan_head_screw_m2x0_40_x_10__2803432263e518bbd16bccbbef8784ed_11 -->
            <geom type="mesh" class="visual" pos="0.00261228 0.000616102 0.00361198" quat="0.817121 -0.217718 0.226424 -0.483368" mesh="ph_pan_head_screw_m2x0_40_x_10__2803432263e518bbd16bccbbef8784ed" material="ph_pan_head_screw_m2x0_40_x_10__2803432263e518bbd16bccbbef8784ed_material"/>
            <!-- Frame closing_ball3_2 -->
            <site group="3" name="closing_ball3_2" pos="-0.00934617 -0.00220428 -0.0129229" quat="0.314056 0.235998 -0.919585 -0.00615592"/>
            <!-- Link std00333_plast_tcb_torx_2_5x8__configuration_copy_of_default_3 -->
            <body name="std00333_plast_tcb_torx_2_5x8__configuration_copy_of_default_3" pos="-0.0108147 -0.000379119 -0.00451009" quat="0.817121 -0.217718 0.226424 -0.483368">
              <!-- Joint from rotule_ball_5 to std00333_plast_tcb_torx_2_5x8__configuration_copy_of_default_3 -->
              <joint axis="0 0 1" name="passive2 (3)" type="hinge"/>
              <inertial pos="-0.0049016 -0.00891862 0.00225" mass="0.00201325" fullinertia="9.7548e-08 4.2802e-08 1.16807e-07 -4.3109e-08 -0 -0"/>
              <!-- Part gimbal_3 -->
              <geom type="mesh" class="visual" pos="-0.00288986 -0.0052582 0.00225" quat="0.359985 0.608614 0.359985 -0.608614" mesh="gimbal" material="gimbal_material"/>
              <!-- Part std00333_plast_tcb_torx_2_5x8__configuration_copy_of_default_3 -->
              <geom type="mesh" class="visual" pos="-0.0104517 -0.0190172 0.00225" quat="0.608614 -0.359985 0.608614 0.359985" mesh="std00333_plast_tcb_torx_2_5x8__configuration_copy_of_default" material="std00333_plast_tcb_torx_2_5x8__configuration_copy_of_default_material"/>
              <!-- Part plain_washer_large_grade_a_m2_5__9a369f0dc77bf9c598cdf3fb468977e5_3 -->
              <geom type="mesh" class="visual" pos="-0.00953654 -0.0173521 0.00225" quat="0.359985 0.608614 0.359985 -0.608614" mesh="plain_washer_large_grade_a_m2_5__9a369f0dc77bf9c598cdf3fb468977e5" material="plain_washer_large_grade_a_m2_5__9a369f0dc77bf9c598cdf3fb468977e5_material"/>
              <!-- Part parallel_pin_2_x_10__fee063fca0c8b40e46bbc4ffff61d999_5 -->
              <geom type="mesh" class="visual" pos="0 -0 0.00225" quat="0.86071 0 0 0.509095" mesh="parallel_pin_2_x_10__fee063fca0c8b40e46bbc4ffff61d999" material="parallel_pin_2_x_10__fee063fca0c8b40e46bbc4ffff61d999_material"/>
              <!-- Frame closing_1 (3)_1 -->
              <site group="3" name="closing_1 (3)_1" pos="-0.00457561 -0.00832549 0.00225" quat="0.359985 0.608614 0.359985 -0.608614"/>
              <!-- Frame closing_1 (3)_1_z -->
              <site group="3" name="closing_1 (3)_1_z" pos="-0.05274 -0.0959622 0.00225" quat="0.359985 0.608614 0.359985 -0.608614"/>
              <!-- Frame closing_3 (3)_2 -->
              <site group="3" name="closing_3 (3)_2" pos="-0.00288986 -0.0052582 -0.00275" quat="0.968599 0 0 -0.248629"/>
              <!-- Frame closing_3 (3)_2_z -->
              <site group="3" name="closing_3 (3)_2_z" pos="-0.00288986 -0.0052582 0.09725" quat="0.968599 0 0 -0.248629"/>
            </body>
            <!-- Link parallel_pin_2_x_10__fee063fca0c8b40e46bbc4ffff61d999_3 -->
            <body name="parallel_pin_2_x_10__fee063fca0c8b40e46bbc4ffff61d999_3" pos="0.00474009 -0.0485439 -0.00280994" quat="0.217718 0.817121 -0.483368 -0.226424">
              <!-- Joint from rotule_ball_5 to parallel_pin_2_x_10__fee063fca0c8b40e46bbc4ffff61d999_3 -->
              <joint axis="0 0 1" name="passive4 (3)" type="hinge"/>
              <inertial pos="0.0150962 -0.0127974 0.00225" mass="0.00540375" fullinertia="3.33567e-07 5.77676e-07 7.69492e-07 3.27688e-07 -0 -0"/>
              <!-- Part std00447_thermoplastique_m2_5x6__configuration_default_9 -->
              <geom type="mesh" class="visual" pos="0.0201331 -0.0157613 -0.00735" quat="0.860105 -0 -0 0.510117" mesh="std00447_thermoplastique_m2_5x6__configuration_default" material="std00447_thermoplastique_m2_5x6__configuration_default_material"/>
              <!-- Part std00447_thermoplastique_m2_5x6__configuration_default_10 -->
              <geom type="mesh" class="visual" pos="0.0201331 -0.0157613 0.01185" quat="0 0.860105 0.510117 0" mesh="std00447_thermoplastique_m2_5x6__configuration_default" material="std00447_thermoplastique_m2_5x6__configuration_default_material"/>
              <!-- Part parallel_pin_2_x_10__fee063fca0c8b40e46bbc4ffff61d999_6 -->
              <geom type="mesh" class="visual" pos="-0 -0 0.00225" quat="0 0.510117 -0.860105 0" mesh="parallel_pin_2_x_10__fee063fca0c8b40e46bbc4ffff61d999" material="parallel_pin_2_x_10__fee063fca0c8b40e46bbc4ffff61d999_material"/>
              <!-- Part distal_3 -->
              <geom type="mesh" class="visual" pos="-0.0457364 0.0189381 0.00225" quat="0.360707 -0.608186 -0.360707 -0.608186" mesh="distal" material="distal_material"/>
              <!-- Part distal_shell_3 -->
              <geom type="mesh" class="visual" pos="-0.0457364 0.0189381 0.00225" quat="0.360707 -0.608186 -0.360707 -0.608186" mesh="distal_shell" material="distal_shell_material"/>
              <!-- Frame tip3 -->
              <site group="3" name="tip3" pos="0.0283456 -0.0266027 0.00225" quat="0.348133 -0.348133 0.61547 -0.61547"/>
              <!-- Link parallel_pin_2_x_16__da4b7ddbe9d803fe3fbc70f2e822b99b_3 -->
              <body name="parallel_pin_2_x_16__da4b7ddbe9d803fe3fbc70f2e822b99b_3" pos="-0.000105947 -0.00599906 0.00655" quat="0 -1 -0.000555496 -0">
                <!-- Joint from parallel_pin_2_x_10__fee063fca0c8b40e46bbc4ffff61d999_3 to parallel_pin_2_x_16__da4b7ddbe9d803fe3fbc70f2e822b99b_3 -->
                <joint axis="0 0 1" name="passive_5 (3)" type="hinge"/>
                <inertial pos="-0.0249171 -0.00392936 0.0052354" mass="0.0101851" fullinertia="4.96149e-07 2.52849e-06 2.3577e-06 2.4514e-08 1.19e-10 3.04e-10"/>
                <!-- Part proximal_shell_3 -->
                <geom type="mesh" class="visual" pos="-0.052 0 0.00515" quat="0.5 0.5 0.5 -0.5" mesh="proximal_shell" material="proximal_shell_material"/>
                <!-- Part std00447_thermoplastique_m2_5x6__configuration_default_11 -->
                <geom type="mesh" class="visual" pos="-0.022 -0.004 -0.00655" quat="0.707107 0 0 -0.707107" mesh="std00447_thermoplastique_m2_5x6__configuration_default" material="std00447_thermoplastique_m2_5x6__configuration_default_material"/>
                <!-- Part proximal_3 -->
                <geom type="mesh" class="visual" pos="-0.052 0 0.00525" quat="0.5 0.5 0.5 -0.5" mesh="proximal" material="proximal_material"/>
                <!-- Part parallel_pin_2_x_16__da4b7ddbe9d803fe3fbc70f2e822b99b_5 -->
                <geom type="mesh" class="visual" pos="-0.052 0 0.00515" quat="0.707107 0 -0 -0.707107" mesh="parallel_pin_2_x_16__da4b7ddbe9d803fe3fbc70f2e822b99b" material="parallel_pin_2_x_16__da4b7ddbe9d803fe3fbc70f2e822b99b_material"/>
                <!-- Part std00447_thermoplastique_m2_5x6__configuration_default_12 -->
                <geom type="mesh" class="visual" pos="-0.022 -0.004 0.01685" quat="0 -0.707107 0.707107 0" mesh="std00447_thermoplastique_m2_5x6__configuration_default" material="std00447_thermoplastique_m2_5x6__configuration_default_material"/>
                <!-- Part parallel_pin_2_x_16__da4b7ddbe9d803fe3fbc70f2e822b99b_6 -->
                <geom type="mesh" class="visual" pos="-0 -0 0.00515" quat="0.707107 0 -0 -0.707107" mesh="parallel_pin_2_x_16__da4b7ddbe9d803fe3fbc70f2e822b99b" material="parallel_pin_2_x_16__da4b7ddbe9d803fe3fbc70f2e822b99b_material"/>
                <!-- Frame closing_3 (3)_1 -->
                <site group="3" name="closing_3 (3)_1" pos="-0.052 0 0" quat="1 0 -0 0"/>
                <!-- Frame closing_3 (3)_1_z -->
                <site group="3" name="closing_3 (3)_1_z" pos="-0.052 0 0.1" quat="1 0 -0 0"/>
              </body>
            </body>
          </body>
        </body>
      </body>
      <!-- Link rotule_ball_6 -->
      <body name="rotule_ball_6" pos="-0.0046 0.0307993 0.0539855" quat="0.527542 0.470849 -0.527542 -0.470849">
        <!-- Joint from l_wrist_interface to rotule_ball_6 -->
        <joint axis="0 0 1" name="finger3_motor2" type="hinge" range="-1.3962634015954156 1.3962634015955115"/>
        <inertial pos="0.006 0 -0.00345938" mass="0.000410988" fullinertia="4.636e-09 4.636e-09 1e-09 0 -0 0"/>
        <!-- Part rotule_ball_12 -->
        <geom type="mesh" class="visual" pos="0.006 0 -0.0038" quat="0 0 -0 1" mesh="rotule_ball" material="rotule_ball_material"/>
        <!-- Part custom_servo_horn_6 -->
        <geom type="mesh" class="visual" pos="0 0 0.00340001" quat="0 1 0 0" mesh="custom_servo_horn" material="custom_servo_horn_material"/>
        <!-- Part ph_pan_head_screw_m2x0_40_x_10__2803432263e518bbd16bccbbef8784ed_12 -->
        <geom type="mesh" class="visual" pos="0.006 0 -0.0083" quat="0 0.707107 -0.707107 -0" mesh="ph_pan_head_screw_m2x0_40_x_10__2803432263e518bbd16bccbbef8784ed" material="ph_pan_head_screw_m2x0_40_x_10__2803432263e518bbd16bccbbef8784ed_material"/>
        <!-- Link ball_link_5 -->
        <body name="ball_link_5" pos="0.006 0 -0.0038" quat="0.0597009 0.389757 0.00127801 -0.91898">
          <!-- Joint from rotule_ball_6 to ball_link_5 -->
          <joint axis="0 0 1" name="passive_ball9" type="ball"/>
          <inertial pos="-0 -0.0165 -0" mass="0.000463323" fullinertia="6.4012e-08 1.597e-09 6.4012e-08 0 -0 -0"/>
          <!-- Part rotule_lever_11 -->
          <geom type="mesh" class="visual" pos="0 0 0" quat="1 0 -0 -0" mesh="rotule_lever" material="rotule_lever_material"/>
          <!-- Part rotule_lever_12 -->
          <geom type="mesh" class="visual" pos="0 -0.033 0" quat="0 0.707107 0 0.707107" mesh="rotule_lever" material="rotule_lever_material"/>
          <!-- Part m2_rod_l18_6 -->
          <geom type="mesh" class="visual" pos="-0 0.0005 -0" quat="0.707107 0 0.707107 -0" mesh="m2_rod_l18" material="m2_rod_l18_material"/>
          <!-- Part spacer_6 -->
          <geom type="mesh" class="visual" pos="-0 -0 -0" quat="0.707107 -0 0.707107 -0" mesh="spacer" material="spacer_material"/>
          <!-- Frame closing_ball3_1 -->
          <site group="3" name="closing_ball3_1" pos="0 -0.033 0" quat="0 0.707107 0 0.707107"/>
        </body>
      </body>
      <!-- Link custom_servo_horn_4 -->
      <body name="custom_servo_horn_4" pos="-0.00406342 -0.0192398 0.0366" quat="0 -0.573576 0.819152 -0">
        <!-- Joint from l_wrist_interface to custom_servo_horn_4 -->
        <joint axis="0 0 1" name="finger4_motor1" type="hinge" range="-1.3962634015954856 1.3962634015954418"/>
        <inertial pos="0.006 0 -0.00345938" mass="0.000410988" fullinertia="4.636e-09 4.636e-09 1e-09 -0 -0 0"/>
        <!-- Part rotule_ball_13 -->
        <geom type="mesh" class="visual" pos="0.006 0 -0.0038" quat="0 -0 -0 -1" mesh="rotule_ball" material="rotule_ball_material"/>
        <!-- Part custom_servo_horn_7 -->
        <geom type="mesh" class="visual" pos="-0 0 0.00340001" quat="0 1 0 0" mesh="custom_servo_horn" material="custom_servo_horn_material"/>
        <!-- Part ph_pan_head_screw_m2x0_40_x_10__2803432263e518bbd16bccbbef8784ed_13 -->
        <geom type="mesh" class="visual" pos="0.006 0 -0.0083" quat="0 0.707107 -0.707107 -0" mesh="ph_pan_head_screw_m2x0_40_x_10__2803432263e518bbd16bccbbef8784ed" material="ph_pan_head_screw_m2x0_40_x_10__2803432263e518bbd16bccbbef8784ed_material"/>
        <!-- Link ball_link_6 -->
        <body name="ball_link_6" pos="0.006 0 -0.0038" quat="0.0416652 -0.065031 -0.996702 -0.0248859">
          <!-- Joint from custom_servo_horn_4 to ball_link_6 -->
          <joint axis="0 0 1" name="passive_ball10" type="ball"/>
          <inertial pos="-0 -0.0165 -0" mass="0.000463323" fullinertia="6.4012e-08 1.597e-09 6.4012e-08 0 -0 -0"/>
          <!-- Part rotule_lever_13 -->
          <geom type="mesh" class="visual" pos="0 -0.033 0" quat="0 0.707107 0 0.707107" mesh="rotule_lever" material="rotule_lever_material"/>
          <!-- Part rotule_lever_14 -->
          <geom type="mesh" class="visual" pos="0 -0 0" quat="1 -0 -0 0" mesh="rotule_lever" material="rotule_lever_material"/>
          <!-- Part m2_rod_l18_7 -->
          <geom type="mesh" class="visual" pos="0 -0.0335 0" quat="0 0 -0 -1" mesh="m2_rod_l18" material="m2_rod_l18_material"/>
          <!-- Part spacer_7 -->
          <geom type="mesh" class="visual" pos="0 -0.033 0" quat="0 0 -0 -1" mesh="spacer" material="spacer_material"/>
          <!-- Link rotule_ball_7 -->
          <body name="rotule_ball_7" pos="0 -0.033 0" quat="0.707107 -0 -0.707107 0">
            <!-- Joint from ball_link_6 to rotule_ball_7 -->
            <joint axis="0 0 1" name="passive_ball11" type="ball"/>
            <inertial pos="-0.000354141 -0.014351 -0.00619144" mass="0.00277119" fullinertia="8.07721e-07 1.02879e-07 7.58343e-07 5.3976e-08 -4.622e-09 9.7154e-08"/>
            <!-- Part rotule_ball_14 -->
            <geom type="mesh" class="visual" pos="-0 0 -0" quat="0.0758695 0.97145 0.223555 0.0234733" mesh="rotule_ball" material="rotule_ball_material"/>
            <!-- Part link_4 -->
            <geom type="mesh" class="visual" pos="-0.0108428 -0.00274643 -0.00864535" quat="0.211725 0.703517 0.10443 -0.670321" mesh="link" material="link_material"/>
            <!-- Part ph_pan_head_screw_m2x0_40_x_10__2803432263e518bbd16bccbbef8784ed_14 -->
            <geom type="mesh" class="visual" pos="0.00163829 -0.00282038 -0.0203401" quat="0.0370497 0.844997 -0.528842 0.070246" mesh="ph_pan_head_screw_m2x0_40_x_10__2803432263e518bbd16bccbbef8784ed" material="ph_pan_head_screw_m2x0_40_x_10__2803432263e518bbd16bccbbef8784ed_material"/>
            <!-- Part ph_pan_head_screw_m2x0_40_x_10__2803432263e518bbd16bccbbef8784ed_15 -->
            <geom type="mesh" class="visual" pos="-0.000357878 0.000616102 0.00444324" quat="0.844997 -0.0370497 -0.070246 -0.528842" mesh="ph_pan_head_screw_m2x0_40_x_10__2803432263e518bbd16bccbbef8784ed" material="ph_pan_head_screw_m2x0_40_x_10__2803432263e518bbd16bccbbef8784ed_material"/>
            <!-- Part rotule_ball_15 -->
            <geom type="mesh" class="visual" pos="0.00128041 -0.00220428 -0.0158969" quat="0.97145 -0.0758695 -0.0234733 0.223555" mesh="rotule_ball" material="rotule_ball_material"/>
            <!-- Frame closing_ball4_2 -->
            <site group="3" name="closing_ball4_2" pos="0.00128041 -0.00220428 -0.0158969" quat="0.0370497 0.844997 -0.528842 0.070246"/>
            <!-- Link std00333_plast_tcb_torx_2_5x8__configuration_copy_of_default_4 -->
            <body name="std00333_plast_tcb_torx_2_5x8__configuration_copy_of_default_4" pos="-0.00529807 -0.000379119 -0.0104513" quat="0.844997 -0.0370497 -0.070246 -0.528842">
              <!-- Joint from rotule_ball_7 to std00333_plast_tcb_torx_2_5x8__configuration_copy_of_default_4 -->
              <joint axis="0 0 1" name="passive2 (4)" type="hinge"/>
              <inertial pos="-0.0049016 -0.00891862 0.00225" mass="0.00201325" fullinertia="9.7548e-08 4.2802e-08 1.16807e-07 -4.3109e-08 -0 -0"/>
              <!-- Part parallel_pin_2_x_10__fee063fca0c8b40e46bbc4ffff61d999_7 -->
              <geom type="mesh" class="visual" pos="-0 0 0.00225" quat="0.86071 -0 0 0.509095" mesh="parallel_pin_2_x_10__fee063fca0c8b40e46bbc4ffff61d999" material="parallel_pin_2_x_10__fee063fca0c8b40e46bbc4ffff61d999_material"/>
              <!-- Part plain_washer_large_grade_a_m2_5__9a369f0dc77bf9c598cdf3fb468977e5_4 -->
              <geom type="mesh" class="visual" pos="-0.00953654 -0.0173521 0.00225" quat="0.359985 0.608614 0.359985 -0.608614" mesh="plain_washer_large_grade_a_m2_5__9a369f0dc77bf9c598cdf3fb468977e5" material="plain_washer_large_grade_a_m2_5__9a369f0dc77bf9c598cdf3fb468977e5_material"/>
              <!-- Part gimbal_4 -->
              <geom type="mesh" class="visual" pos="-0.00288986 -0.0052582 0.00225" quat="0.359985 0.608614 0.359985 -0.608614" mesh="gimbal" material="gimbal_material"/>
              <!-- Part std00333_plast_tcb_torx_2_5x8__configuration_copy_of_default_4 -->
              <geom type="mesh" class="visual" pos="-0.0104517 -0.0190172 0.00225" quat="0.608614 -0.359985 0.608614 0.359985" mesh="std00333_plast_tcb_torx_2_5x8__configuration_copy_of_default" material="std00333_plast_tcb_torx_2_5x8__configuration_copy_of_default_material"/>
              <!-- Frame closing_1 (4)_1 -->
              <site group="3" name="closing_1 (4)_1" pos="-0.00457561 -0.00832549 0.00225" quat="0.359985 0.608614 0.359985 -0.608614"/>
              <!-- Frame closing_1 (4)_1_z -->
              <site group="3" name="closing_1 (4)_1_z" pos="-0.05274 -0.0959622 0.00225" quat="0.359985 0.608614 0.359985 -0.608614"/>
              <!-- Frame closing_3 (4)_2 -->
              <site group="3" name="closing_3 (4)_2" pos="-0.00288986 -0.0052582 -0.00275" quat="0.968599 0 -0 -0.248629"/>
              <!-- Frame closing_3 (4)_2_z -->
              <site group="3" name="closing_3 (4)_2_z" pos="-0.00288986 -0.0052582 0.09725" quat="0.968599 0 -0 -0.248629"/>
            </body>
            <!-- Link parallel_pin_2_x_10__fee063fca0c8b40e46bbc4ffff61d999_4 -->
            <body name="parallel_pin_2_x_10__fee063fca0c8b40e46bbc4ffff61d999_4" pos="0.00542962 -0.0485439 0.000939894" quat="0.0370497 0.844997 -0.528842 0.070246">
              <!-- Joint from rotule_ball_7 to parallel_pin_2_x_10__fee063fca0c8b40e46bbc4ffff61d999_4 -->
              <joint axis="0 0 1" name="passive4 (4)" type="hinge"/>
              <inertial pos="0.0150962 -0.0127974 0.00225" mass="0.00540375" fullinertia="3.33567e-07 5.77676e-07 7.69492e-07 3.27688e-07 0 0"/>
              <!-- Part distal_shell_4 -->
              <geom type="mesh" class="visual" pos="-0.0457364 0.0189381 0.00225" quat="0.360707 -0.608186 -0.360707 -0.608186" mesh="distal_shell" material="distal_shell_material"/>
              <!-- Part std00447_thermoplastique_m2_5x6__configuration_default_13 -->
              <geom type="mesh" class="visual" pos="0.0201331 -0.0157613 0.01185" quat="0 -0.860105 -0.510117 0" mesh="std00447_thermoplastique_m2_5x6__configuration_default" material="std00447_thermoplastique_m2_5x6__configuration_default_material"/>
              <!-- Part parallel_pin_2_x_10__fee063fca0c8b40e46bbc4ffff61d999_8 -->
              <geom type="mesh" class="visual" pos="0 0 0.00225" quat="0 0.510117 -0.860105 -0" mesh="parallel_pin_2_x_10__fee063fca0c8b40e46bbc4ffff61d999" material="parallel_pin_2_x_10__fee063fca0c8b40e46bbc4ffff61d999_material"/>
              <!-- Part distal_4 -->
              <geom type="mesh" class="visual" pos="-0.0457364 0.0189381 0.00225" quat="0.360707 -0.608186 -0.360707 -0.608186" mesh="distal" material="distal_material"/>
              <!-- Part std00447_thermoplastique_m2_5x6__configuration_default_14 -->
              <geom type="mesh" class="visual" pos="0.0201331 -0.0157613 -0.00735" quat="0.860105 -0 0 0.510117" mesh="std00447_thermoplastique_m2_5x6__configuration_default" material="std00447_thermoplastique_m2_5x6__configuration_default_material"/>
              <!-- Frame tip4 -->
              <site group="3" name="tip4" pos="0.0283456 -0.0266027 0.00225" quat="0.61547 0.61547 0.348133 0.348133"/>
              <!-- Link parallel_pin_2_x_16__da4b7ddbe9d803fe3fbc70f2e822b99b_4 -->
              <body name="parallel_pin_2_x_16__da4b7ddbe9d803fe3fbc70f2e822b99b_4" pos="-0.000105947 -0.00599906 0.00655" quat="0 -1 -0.000555496 -0">
                <!-- Joint from parallel_pin_2_x_10__fee063fca0c8b40e46bbc4ffff61d999_4 to parallel_pin_2_x_16__da4b7ddbe9d803fe3fbc70f2e822b99b_4 -->
                <joint axis="0 0 1" name="passive_5 (4)" type="hinge"/>
                <inertial pos="-0.0249171 -0.00392936 0.0052354" mass="0.0101851" fullinertia="4.96149e-07 2.52849e-06 2.3577e-06 2.4514e-08 1.19e-10 3.04e-10"/>
                <!-- Part std00447_thermoplastique_m2_5x6__configuration_default_15 -->
                <geom type="mesh" class="visual" pos="-0.022 -0.004 0.01685" quat="0 0.707107 -0.707107 -0" mesh="std00447_thermoplastique_m2_5x6__configuration_default" material="std00447_thermoplastique_m2_5x6__configuration_default_material"/>
                <!-- Part parallel_pin_2_x_16__da4b7ddbe9d803fe3fbc70f2e822b99b_7 -->
                <geom type="mesh" class="visual" pos="-0.052 -0 0.00515" quat="0.707107 0 0 -0.707107" mesh="parallel_pin_2_x_16__da4b7ddbe9d803fe3fbc70f2e822b99b" material="parallel_pin_2_x_16__da4b7ddbe9d803fe3fbc70f2e822b99b_material"/>
                <!-- Part parallel_pin_2_x_16__da4b7ddbe9d803fe3fbc70f2e822b99b_8 -->
                <geom type="mesh" class="visual" pos="0 -0 0.00515" quat="0.707107 0 -0 -0.707107" mesh="parallel_pin_2_x_16__da4b7ddbe9d803fe3fbc70f2e822b99b" material="parallel_pin_2_x_16__da4b7ddbe9d803fe3fbc70f2e822b99b_material"/>
                <!-- Part proximal_shell_4 -->
                <geom type="mesh" class="visual" pos="-0.052 0 0.00515" quat="0.5 0.5 0.5 -0.5" mesh="proximal_shell" material="proximal_shell_material"/>
                <!-- Part proximal_4 -->
                <geom type="mesh" class="visual" pos="-0.052 0 0.00525" quat="0.5 0.5 0.5 -0.5" mesh="proximal" material="proximal_material"/>
                <!-- Part std00447_thermoplastique_m2_5x6__configuration_default_16 -->
                <geom type="mesh" class="visual" pos="-0.022 -0.004 -0.00655" quat="0.707107 -0 0 -0.707107" mesh="std00447_thermoplastique_m2_5x6__configuration_default" material="std00447_thermoplastique_m2_5x6__configuration_default_material"/>
                <!-- Frame closing_3 (4)_1 -->
                <site group="3" name="closing_3 (4)_1" pos="-0.052 0 -0" quat="1 0 0 0"/>
                <!-- Frame closing_3 (4)_1_z -->
                <site group="3" name="closing_3 (4)_1_z" pos="-0.052 0 0.1" quat="1 0 0 0"/>
              </body>
            </body>
          </body>
        </body>
      </body>
      <!-- Link rotule_ball_8 -->
      <body name="rotule_ball_8" pos="7.5027e-05 -0.00786953 0.0366" quat="0 0.819152 0.573576 0">
        <!-- Joint from l_wrist_interface to rotule_ball_8 -->
        <joint axis="0 0 1" name="finger4_motor2" type="hinge" range="-1.3962634018157374 1.3962634013751898"/>
        <inertial pos="0.006 0 -0.00345938" mass="0.000410988" fullinertia="4.636e-09 4.636e-09 1e-09 0 0 0"/>
        <!-- Part ph_pan_head_screw_m2x0_40_x_10__2803432263e518bbd16bccbbef8784ed_16 -->
        <geom type="mesh" class="visual" pos="0.006 0 -0.0083" quat="0 0.707107 -0.707107 0" mesh="ph_pan_head_screw_m2x0_40_x_10__2803432263e518bbd16bccbbef8784ed" material="ph_pan_head_screw_m2x0_40_x_10__2803432263e518bbd16bccbbef8784ed_material"/>
        <!-- Part rotule_ball_16 -->
        <geom type="mesh" class="visual" pos="0.006 0 -0.0038" quat="0 -0 -0 1" mesh="rotule_ball" material="rotule_ball_material"/>
        <!-- Part custom_servo_horn_8 -->
        <geom type="mesh" class="visual" pos="0 0 0.00340001" quat="0 1 0 0" mesh="custom_servo_horn" material="custom_servo_horn_material"/>
        <!-- Link ball_link_7 -->
        <body name="ball_link_7" pos="0.006 0 -0.0038" quat="0.0227479 0.998154 0.055212 -0.0110773">
          <!-- Joint from rotule_ball_8 to ball_link_7 -->
          <joint axis="0 0 1" name="passive_ball12" type="ball"/>
          <inertial pos="-0 -0.0165 -0" mass="0.000463323" fullinertia="6.4012e-08 1.597e-09 6.4012e-08 0 -0 -0"/>
          <!-- Part rotule_lever_15 -->
          <geom type="mesh" class="visual" pos="-0 -0.033 0" quat="0 0.707107 0 0.707107" mesh="rotule_lever" material="rotule_lever_material"/>
          <!-- Part rotule_lever_16 -->
          <geom type="mesh" class="visual" pos="-0 -0 0" quat="1 0 0 0" mesh="rotule_lever" material="rotule_lever_material"/>
          <!-- Part m2_rod_l18_8 -->
          <geom type="mesh" class="visual" pos="-0 -0.0335 0" quat="0 -0 0 -1" mesh="m2_rod_l18" material="m2_rod_l18_material"/>
          <!-- Part spacer_8 -->
          <geom type="mesh" class="visual" pos="-0 -0.033 0" quat="0 0 0 -1" mesh="spacer" material="spacer_material"/>
          <!-- Frame closing_ball4_1 -->
          <site group="3" name="closing_ball4_1" pos="-0 -0.033 0" quat="0 0.707107 0 0.707107"/>
        </body>
      </body>
    </body>
  </worldbody>
  <asset>
    <mesh file="spacer.stl"/>
    <mesh file="custom_servo_horn.stl"/>
    <mesh file="parallel_pin_2_x_10__fee063fca0c8b40e46bbc4ffff61d999.stl"/>
    <mesh file="proximal.stl"/>
    <mesh file="proximal_shell.stl"/>
    <mesh file="distal.stl"/>
    <mesh file="l_wrist_interface.stl"/>
    <mesh file="rotule_ball.stl"/>
    <mesh file="std00447_thermoplastique_m2_5x6__configuration_default.stl"/>
    <mesh file="bushing_0608_04.stl"/>
    <mesh file="finger_frame.stl"/>
    <mesh file="distal_shell.stl"/>
    <mesh file="link.stl"/>
    <mesh file="l_hand_plate.stl"/>
    <mesh file="ph_pan_head_screw_m2x0_40_x_10__2803432263e518bbd16bccbbef8784ed.stl"/>
    <mesh file="rotule_lever.stl"/>
    <mesh file="plain_washer_large_grade_a_m2_5__9a369f0dc77bf9c598cdf3fb468977e5.stl"/>
    <mesh file="std00333_plast_tcb_torx_2_5x8__configuration_copy_of_default.stl"/>
    <mesh file="m2_rod_l18.stl"/>
    <mesh file="gimbal.stl"/>
    <mesh file="parallel_pin_2_x_16__da4b7ddbe9d803fe3fbc70f2e822b99b.stl"/>
    <mesh file="sts3032.stl"/>
    <material name="sts3032_material" rgba="0.972549 0.529412 0.00392157 1"/>
    <material name="finger_frame_material" rgba="0.8 0.8 0.8 1"/>
    <material name="bushing_0608_04_material" rgba="0.301961 0.301961 0.301961 1"/>
    <material name="l_hand_plate_material" rgba="0.301961 0.301961 0.301961 1"/>
    <material name="l_wrist_interface_material" rgba="0.301961 0.301961 0.301961 1"/>
    <material name="rotule_ball_material" rgba="0.960784 0.835294 0.470588 1"/>
    <material name="ph_pan_head_screw_m2x0_40_x_10__2803432263e518bbd16bccbbef8784ed_material" rgba="0.603922 0.647059 0.686275 1"/>
    <material name="custom_servo_horn_material" rgba="1 1 1 1"/>
    <material name="rotule_lever_material" rgba="0.196078 0.196078 0.196078 1"/>
    <material name="m2_rod_l18_material" rgba="0.811765 0.858824 0.898039 1"/>
    <material name="spacer_material" rgba="0.501961 0.501961 0.501961 1"/>
    <material name="link_material" rgba="0.8 0.8 0.8 1"/>
    <material name="std00333_plast_tcb_torx_2_5x8__configuration_copy_of_default_material" rgba="0.901961 0.901961 0.901961 1"/>
    <material name="gimbal_material" rgba="0.8 0.8 0.8 1"/>
    <material name="plain_washer_large_grade_a_m2_5__9a369f0dc77bf9c598cdf3fb468977e5_material" rgba="0.603922 0.647059 0.686275 1"/>
    <material name="parallel_pin_2_x_10__fee063fca0c8b40e46bbc4ffff61d999_material" rgba="0.603922 0.647059 0.686275 1"/>
    <material name="std00447_thermoplastique_m2_5x6__configuration_default_material" rgba="0.901961 0.901961 0.901961 1"/>
    <material name="distal_material" rgba="0.8 0.8 0.8 1"/>
    <material name="distal_shell_material" rgba="1 1 1 1"/>
    <material name="parallel_pin_2_x_16__da4b7ddbe9d803fe3fbc70f2e822b99b_material" rgba="0.603922 0.647059 0.686275 1"/>
    <material name="proximal_shell_material" rgba="1 1 1 1"/>
    <material name="proximal_material" rgba="0.8 0.8 0.8 1"/>
  </asset>
  <actuator>
    <position class="onshape_to_robot_69e9f0da9e87b1.61053623" name="finger1_motor1" joint="finger1_motor1" inheritrange="1"/>
    <position class="onshape_to_robot_69e9f0da9e87b1.61053623" name="finger1_motor2" joint="finger1_motor2" inheritrange="1"/>
    <position class="onshape_to_robot_69e9f0da9e87b1.61053623" name="finger2_motor1" joint="finger2_motor1" inheritrange="1"/>
    <position class="onshape_to_robot_69e9f0da9e87b1.61053623" name="finger2_motor2" joint="finger2_motor2" inheritrange="1"/>
    <position class="onshape_to_robot_69e9f0da9e87b1.61053623" name="finger3_motor1" joint="finger3_motor1" inheritrange="1"/>
    <position class="onshape_to_robot_69e9f0da9e87b1.61053623" name="finger3_motor2" joint="finger3_motor2" inheritrange="1"/>
    <position class="onshape_to_robot_69e9f0da9e87b1.61053623" name="finger4_motor1" joint="finger4_motor1" inheritrange="1"/>
    <position class="onshape_to_robot_69e9f0da9e87b1.61053623" name="finger4_motor2" joint="finger4_motor2" inheritrange="1"/>
  </actuator>
  <equality>
    <connect site1="closing_1 (1)_1" site2="closing_1 (1)_2"/>
    <connect site1="closing_1 (1)_1_z" site2="closing_1 (1)_2_z"/>
    <connect site1="closing_3 (1)_1" site2="closing_3 (1)_2"/>
    <connect site1="closing_3 (1)_1_z" site2="closing_3 (1)_2_z"/>
    <connect site1="closing_1 (2)_1" site2="closing_1 (2)_2"/>
    <connect site1="closing_1 (2)_1_z" site2="closing_1 (2)_2_z"/>
    <connect site1="closing_3 (2)_1" site2="closing_3 (2)_2"/>
    <connect site1="closing_3 (2)_1_z" site2="closing_3 (2)_2_z"/>
    <connect site1="closing_1 (3)_1" site2="closing_1 (3)_2"/>
    <connect site1="closing_1 (3)_1_z" site2="closing_1 (3)_2_z"/>
    <connect site1="closing_3 (3)_1" site2="closing_3 (3)_2"/>
    <connect site1="closing_3 (3)_1_z" site2="closing_3 (3)_2_z"/>
    <connect site1="closing_1 (4)_1" site2="closing_1 (4)_2"/>
    <connect site1="closing_1 (4)_1_z" site2="closing_1 (4)_2_z"/>
    <connect site1="closing_3 (4)_1" site2="closing_3 (4)_2"/>
    <connect site1="closing_3 (4)_1_z" site2="closing_3 (4)_2_z"/>
    <connect site1="closing_ball1_1" site2="closing_ball1_2"/>
    <connect site1="closing_ball2_1" site2="closing_ball2_2"/>
    <connect site1="closing_ball3_1" site2="closing_ball3_2"/>
    <connect site1="closing_ball4_1" site2="closing_ball4_2"/>
  </equality>
</mujoco>
